{"errorMessage": "An error occurred (ResourceNotFoundException) when calling the Scan operation: Requested resource not found", "errorType": "ResourceNotFoundException", "requestId": "8bcc0ed0-9101-49cb-b011-8a5139b63c41", "stackTrace": ["  File \"/var/task/app.py\", line 29, in lambda_handler\n    return response(200, todos_persons_table.scan()[\"Items\"])\n", "  File \"/var/lang/lib/python3.12/site-packages/boto3/resources/factory.py\", line 580, in do_action\n    response = action(self, *args, **kwargs)\n", "  File \"/var/lang/lib/python3.12/site-packages/boto3/resources/action.py\", line 88, in __call__\n    response = getattr(parent.meta.client, operation_name)(*args, **params)\n", "  File \"/var/lang/lib/python3.12/site-packages/botocore/client.py\", line 535, in _api_call\n    return self._make_api_call(operation_name, kwargs)\n", "  File \"/var/lang/lib/python3.12/site-packages/botocore/client.py\", line 980, in _make_api_call\n    raise error_class(parsed_response, operation_name)\n"]}